Workbook

Sheet Thong_tin
A1: BỘ BIỂU MẪU KIỂM THỬ – VAI TESTER
A2: Học phần Đánh giá hiệu năng · Dùng cho hệ thống của bạn cặp
B4: Tester – Họ và tên | C4: Lương Chí Dũng
B5: Tester – MSSV | C5: 24110215
B6: Lớp | C6: BCSE2024 - Trường Đại học Việt Nhật (VJU)
B7: Hệ thống được kiểm thử | C7: RateProfCuaBan (RateUrProf)
B8: Chủ hệ thống – Họ tên, MSSV | C8: Lương Chí Dũng - 24110215
B9: Link sản phẩm | C9: https://rateurprofs.site
B10: Phiên bản SRS dùng làm căn cứ | C10: SRS v1.2 (bản chốt sau review)
B11: Thời gian kiểm thử (từ – đến) | C11: 05/10/2026 – 26/10/2026
B13: CÁC SHEET TRONG FILE
B14: Review_SRS | C14: Phiếu review SRS (tuần 5). Chủ hệ thống điền 2 cột phản hồi cuối.
B15: TC_Chuc_nang | C15: Test case chức năng, luồng E2E và phân quyền. Tối thiểu 60 case, phủ hết chức năng và 3 luồng.
B16: TC_Phi_chuc_nang | C16: Test case phi chức năng. Tối thiểu 10 case, phủ hết NFR trong SRS.
B17: Test_Log | C17: Nhật ký mỗi phiên thực thi: thời gian, môi trường, phạm vi đã chạy, kết quả.
B18: Bug_Report | C18: Danh sách lỗi. Mỗi lỗi ghi rõ 1 trong 5 loại: Functional, Visual, Content, Performance, Crash.
B19: Tong_hop | C19: Tự tính số liệu để đưa vào Test Summary Report. Không cần điền.
A21: Chú thích: ô nền vàng nhạt = sinh viên điền; dòng chữ xám nghiêng ở đầu mỗi bảng = VÍ DỤ, ghi đè hoặc xoá khi làm; cột có mũi tên = chọn từ danh sách.

Sheet Review_SRS
A1: PHIẾU REVIEW SRS
A2: Tester kiểm tra từng yêu cầu: rõ ràng? kiểm thử được? đầy đủ? nhất quán? Chủ hệ thống điền 2 cột cuối rồi cập nhật SRS.
A3: Chú thích: ô nền vàng nhạt = sinh viên điền; dòng chữ xám nghiêng = VÍ DỤ, ghi đè hoặc xoá khi làm; cột có mũi tên = chọn từ danh sách.
A4: STT | B4: Vị trí trong SRS (mục / mã yêu cầu) | C4: Nội dung trích từ SRS | D4: Vấn đề phát hiện | E4: Loại vấn đề | F4: Mức độ | G4: Đề xuất sửa | H4: Phản hồi của chủ hệ thống | I4: Lý do / cách đã sửa
A5: 1 | B5: FR-06 – Thang điểm đánh giá | C5: "Điểm đánh giá các tiêu chí phải hợp lệ" | D5: Không nêu rõ thang điểm tối thiểu và tối đa (1–5 hay 0–10), không nêu rõ có cho phép điểm thập phân hay không. | E5: Không kiểm thử được | F5: Cao | G5: Quy định rõ: "Điểm là số nguyên từ 1 đến 5 cho từng tiêu chí (pedagogy, difficulty, workEffort, gradingFairness). Cấm điểm < 1 hoặc > 5." | H5: Chấp nhận | I5: Đã bổ sung ràng buộc chặt chẽ tại SRS v1.1 mục 4.6
A6: 2 | B6: FR-08 – Quy định Upvote | C6: "Sinh viên có thể đánh giá tính hữu ích của bài viết" | D6: Không quy định giới hạn số lần upvote cho mỗi người dùng, dẫn đến rủi ro spam vote vô hạn. | E6: Thiếu ràng buộc | F6: Cao | G6: Bổ sung: "Mỗi người dùng/phiên chỉ được upvote 1 lần duy nhất cho mỗi bài đánh giá. Cho phép toggle hủy vote." | H6: Chấp nhận | I6: Đã cập nhật logic kiểm tra khóa phiên tại SRS v1.1 mục 4.8
A7: 3 | B7: FR-01 – Tìm kiếm tiếng Việt | C7: "Tìm kiếm giảng viên nhanh chóng theo tên" | D7: Không nêu rõ có hỗ trợ tiếng Việt không dấu, ký tự unicode tổ hợp (NFC/NFD) hay không. | E7: Mơ hồ | F7: Trung bình | G7: Ghi rõ: "Hỗ trợ tìm kiếm không dấu (accent-insensitive) và chuẩn hóa chuỗi tiếng Việt Unicode NFC; độ nhạy từ 2 ký tự." | H7: Chấp nhận | I7: Đã chuẩn hóa định nghĩa tìm kiếm tại SRS v1.1 mục 4.1
A8: 4 | B8: FR-07 – Phân quyền Quản trị viên | C8: "Admin kiểm duyệt và phê duyệt yêu cầu đính chính" | D8: Chưa định nghĩa rõ cơ chế chặn truy cập trái phép của người dùng vãng lai vào giao diện /admin. | E8: Thiếu ràng buộc | F8: Cao | G8: Bổ sung bảng phân quyền RBAC: "Khách và Thành viên truy cập /admin phải bị chặn ngay lập tức (redirect về /login hoặc HTTP 403 Forbidden)." | H8: Chấp nhận | I8: Đã thêm Ma trận RBAC tại SRS v1.1 mục 5.2
A9: 5 | B9: FR-04 – Lưu giảng viên (Bookmark) | C9: "Người dùng có thể bookmark giảng viên quan tâm" | D9: Chưa quy định cơ chế lưu trữ (LocalStorage hay Database) và thời gian tồn tại sau khi F5/reload. | E9: Mơ hồ | F9: Trung bình | G9: Đặc tả rõ: "Bookmark được lưu bền vững vào LocalStorage (cho khách) và đồng bộ Database khi đăng nhập; tồn tại qua các phiên duyệt web." | H9: Chấp nhận | I9: Đã cập nhật đặc tả lưu trữ bookmark tại SRS v1.1 mục 4.4
A10: 6 | B10: NFR-01 – Hiệu năng tìm kiếm | C10: "Hệ thống phải phản hồi tìm kiếm nhanh chóng" | D10: Dùng từ tính từ định tính 'nhanh chóng', không có số liệu định lượng để kiểm thử hiệu năng. | E10: Không kiểm thử được | F10: Cao | G10: Sửa thành chỉ số định lượng: "P90 response time ≤ 2.0s và error rate < 1% khi chịu tải 20 người dùng đồng thời (20 concurrent threads)." | H10: Chấp nhận | I10: Đã định lượng hóa NFR-01 tại SRS v1.1 mục 6.1
A11: 7 | B11: NFR-02 – Hiệu năng tải trang Web Vitals | C11: "Trang chủ tải mượt mà trên di động" | D11: Thiếu chỉ số kỹ thuật tiêu chuẩn của Google Web Vitals. | E11: Không kiểm thử được | F11: Trung bình | G11: Đặc tả: "Largest Contentful Paint (LCP) ≤ 2.5s trên mạng 4G giả lập; First Input Delay (FID) ≤ 100ms." | H11: Chấp nhận | I11: Đã bổ sung chuẩn Web Vitals tại SRS v1.1 mục 6.2
A12: 8 | B12: NFR-04 – Responsive giao diện | C12: "Giao diện hiển thị tốt trên mọi kích thước màn hình" | D12: Chưa liệt kê các breakpoint kiểm thử cụ thể. | E12: Mơ hồ | F12: Thấp | G12: Ghi rõ các breakpoint: "375x812 (mobile), 768x1024 (tablet), 1366x768 (laptop), 1920x1080 (desktop); tuyệt đối không xuất hiện thanh cuộn ngang." | H12: Chấp nhận | I12: Đã liệt kê các breakpoint tại SRS v1.1 mục 6.4
A13: 9 | B13: FR-11 – Đa ngôn ngữ (i18n) | C13: "Hỗ trợ giao diện tiếng Việt và tiếng Anh" | D13: Chưa làm rõ việc chuyển ngôn ngữ có làm mất trạng thái bộ lọc và từ khóa tìm kiếm đang hiển thị hay không. | E13: Thiếu trường hợp biên | F13: Trung bình | G13: Quy định: "Khi chuyển đổi VI/EN, toàn bộ query parameters trên URL (?q=..., ?dept=...) phải được bảo toàn 100%." | H13: Chấp nhận | I13: Đã bổ sung nguyên tắc bảo toàn state URL tại SRS v1.1 mục 4.11
A14: 10 | B14: NFR-05 – Xử lý lỗi ngoại lệ API | C14: "Hệ thống xử lý lỗi khi người dùng gửi sai" | D14: Chưa quy định định dạng JSON chuẩn của phản hồi lỗi HTTP 400/500. | E14: Thiếu ràng buộc | F14: Trung bình | G14: Quy định chuẩn JSON lỗi: `{"error": "MÃ_LỖI", "message": "Thông điệp", "fields": {...}}`, không bao giờ trả về stack trace HTML hoặc crash 500. | H14: Chấp nhận | I14: Đã thống nhất schema lỗi tại SRS v1.1 mục 6.5 và Tài liệu API mục 2

Sheet TC_Chuc_nang
A1: TEST CASE CHỨC NĂNG
A2: Quy ước mã: TC-FRxx-nnn (chức năng) · TC-FLOWxx-nnn (luồng E2E) · TC-AUTHZ-nnn (phân quyền). Mỗi chức năng ≥ 3 case.
A3: Chú thích: ô nền vàng nhạt = sinh viên điền; dòng chữ xám nghiêng = VÍ DỤ, ghi đè hoặc xoá khi làm; cột có mũi tên = chọn từ danh sách.
A4: TC ID | B4: Chức năng / Luồng | C4: Kỹ thuật thiết kế | D4: Tiêu đề | E4: Tiền điều kiện | F4: Dữ liệu thử | G4: Các bước thực hiện | H4: Kết quả mong đợi | I4: Độ ưu tiên | J4: Kết quả | K4: Kết quả thực tế (khi Fail) | L4: Bug ID | M4: Ghi chú
A5: TC-FR01-001 | B5: FR-01 | C5: Phân hoạch tương đương (EP) | D5: Tìm kiếm giảng viên bằng tên tiếng Việt có dấu đầy đủ | E5: Đang ở trang chủ | F5: Từ khóa: 'Nguyễn Văn A' | G5: 1. Nhập từ khóa 'Nguyễn Văn A' vào ô tìm kiếm 2. Nhấn Enter | H5: Hiển thị danh sách các giảng viên có tên khớp 'Nguyễn Văn A' | I5: High | J5: Pass | M5: Happy path
A6: TC-FR01-002 | B6: FR-01 | C6: Phân hoạch tương đương (EP) | D6: Tìm kiếm bằng tên tiếng Việt không dấu | E6: Đang ở trang chủ | F6: Từ khóa: 'Nguyen Van' | G6: 1. Nhập 'Nguyen Van' vào ô tìm kiếm 2. Nhấn Enter | H6: Hiển thị danh sách giảng viên tương đương có dấu | I6: High | J6: Fail | K6: Báo 0 kết quả, không chuẩn hóa được tiếng Việt không dấu | L6: BUG-004 | M6: Trùng SEED-04
A7: TC-FR01-003 | B7: FR-01 | C7: Giá trị biên (BVA) | D7: Tìm kiếm với độ dài từ khóa = 1 ký tự (dưới biên tối thiểu) | E7: Đang ở trang chủ | F7: Từ khóa: 'N' | G7: 1. Nhập 'N' vào ô tìm kiếm 2. Nhấn Enter | H7: Hiển thị thông báo 'Vui lòng nhập tối thiểu 2 ký tự' | I7: Medium | J7: Pass | M7: Boundary check min-1
A8: TC-FR01-004 | B8: FR-01 | C8: Giá trị biên (BVA) | D8: Tìm kiếm với độ dài từ khóa = 2 ký tự (biên tối thiểu hợp lệ) | E8: Đang ở trang chủ | F8: Từ khóa: 'Lê' | G8: 1. Nhập 'Lê' vào ô tìm kiếm 2. Nhấn Enter | H8: Thực hiện tìm kiếm và hiển thị các giảng viên họ Lê | I8: Medium | J8: Pass | M8: Boundary check valid min
A9: TC-FR01-005 | B9: FR-01 | C9: Phân hoạch tương đương (EP) | D9: Tìm kiếm với từ khóa không tồn tại trong hệ thống | E9: Đang ở trang chủ | F9: Từ khóa: 'xyz_unknown_999' | G9: 1. Nhập từ khóa 2. Nhấn Enter | H9: Hiển thị thông báo 'Không tìm thấy giảng viên phù hợp' | I9: Low | J9: Pass | M9: Negative check
A10: TC-FR02-001 | B10: FR-02 | C10: Phân hoạch tương đương (EP) | D10: Lọc giảng viên theo trường đại học hợp lệ | E10: Đang ở /professors | F10: Chọn trường: VJU | G10: 1. Mở bộ lọc 2. Chọn trường VJU 3. Quan sát kết quả | H10: Chỉ hiển thị giảng viên thuộc VJU | I10: High | J10: Fail | K10: Hiển thị lẫn lộn cả giảng viên HUST | L10: BUG-003 | M10: Trùng SEED-03
A11: TC-FR02-002 | B11: FR-02 | C11: Phân hoạch tương đương (EP) | D11: Lọc theo trường đại học kết hợp từ khóa tìm kiếm | E11: Đang ở /professors | F11: Trường: VNU, Tên: 'Tuấn' | G11: 1. Chọn trường VNU 2. Nhập 'Tuấn' 3. Xem danh sách | H11: Chỉ hiển thị giảng viên tên Tuấn tại ĐHQGHN | I11: Medium | J11: Pass | M11: Filter combination
A12: TC-FR02-003 | B12: FR-02 | C12: Phân hoạch tương đương (EP) | D12: Đặt lại bộ lọc về mặc định (Tất cả trường) | E12: Đang áp dụng bộ lọc trường | F12: Click 'Đặt lại' (Reset) | G12: 1. Bấm nút Đặt lại bộ lọc 2. Quan sát danh sách | H12: Bộ lọc xóa chọn, hiển thị toàn bộ giảng viên | I12: Medium | J12: Pass | M12: Reset filter
A13: TC-FR02-004 | B13: FR-02 | C13: Giá trị biên (BVA) | D13: Chọn lọc trường không có giảng viên nào trong hệ thống | E13: Đang ở /professors | F13: Trường mới tạo chưa có dữ liệu | G13: 1. Chọn trường trống 2. Quan sát danh sách | H13: Hiển thị thông báo 'Chưa có giảng viên nào thuộc trường này' | I13: Low | J13: Pass | M13: Empty list check
A14: TC-FR03-001 | B14: FR-03 | C14: Phân hoạch tương đương (EP) | D14: Xem trang hồ sơ giảng viên tồn tại trong hệ thống | E14: Có giảng viên ID hợp lệ | F14: ID: 'lec_001' | G14: 1. Truy cập /professors/lec_001 2. Quan sát các trường thông tin | H14: Hiển thị đầy đủ Họ tên, Học hàm, Học vị, Trường, Điểm tổng quan | I14: High | J14: Pass | M14: Detail view
A15: TC-FR03-002 | B15: FR-03 | C15: Phân hoạch tương đương (EP) | D15: Xem hồ sơ với avatar tỉ lệ ảnh chữ nhật (3:4 hoặc 16:9) | E15: Giảng viên có avatar chữ nhật | F15: ID: 'lec_rect_avatar' | G15: 1. Truy cập trang chi tiết 2. Kiểm tra khung ảnh avatar | H15: Avatar hiển thị tròn/vuông chuẩn 1:1, không bị dẹt méo | I15: Medium | J15: Fail | K15: Avatar bị dẹt ngang co kéo mất thẩm mỹ | L15: BUG-009 | M15: Trùng SEED-09
A16: TC-FR03-003 | B16: FR-03 | C16: Phân hoạch tương đương (EP) | D16: Xem chi tiết giảng viên bằng mã ID không tồn tại | E16: Đang mở trình duyệt | F16: ID: 'lec_invalid_99999' | G16: 1. Truy cập /professors/lec_invalid_99999 | H16: Hiển thị trang 404 Không tìm thấy giảng viên | I16: Medium | J16: Pass | M16: Not found check
A17: TC-FR03-004 | B17: FR-03 | C17: Phân hoạch tương đương (EP) | D17: Xem phân bố sao đánh giá (Rating Breakdown 1 đến 5 sao) | E17: Giảng viên đã có >= 5 đánh giá | F17: Giảng viên ID: 'lec_001' | G17: 1. Mở trang hồ sơ 2. Cuộn tới phần phân bố sao | H17: Hiển thị thanh tiến trình tỉ lệ phần trăm các mức sao chính xác | I17: Low | J17: Pass | M17: Breakdown check
A18: TC-FR04-001 | B18: FR-04 | C18: Chuyển trạng thái | D18: Lưu giảng viên vào danh sách yêu thích và kiểm tra sau F5 | E18: Trang chi tiết giảng viên | F18: Giảng viên 'lec_001' | G18: 1. Bấm nút Lưu giảng viên 2. F5 tải lại trang 3. Xem trạng thái nút | H18: Nút bookmark vẫn ở trạng thái 'Đã lưu' | I18: High | J18: Fail | K18: F5 xong trạng thái bookmark bị mất về ban đầu | L18: BUG-005 | M18: Trùng SEED-05
A19: TC-FR04-002 | B19: FR-04 | C19: Chuyển trạng thái | D19: Bỏ lưu giảng viên đã được bookmark | E19: Giảng viên đã lưu trước đó | F19: Giảng viên 'lec_001' | G19: 1. Bấm vào nút bookmark đang active 2. Kiểm tra giao diện | H19: Nút chuyển về trạng thái Chưa lưu, xóa khỏi danh sách đã lưu | I19: Medium | J19: Pass | M19: Unbookmark toggle
A20: TC-FR04-003 | B20: FR-04 | C20: Phân hoạch tương đương (EP) | D20: Kiểm tra danh sách giảng viên đã lưu khi lưu nhiều người | E20: Đã lưu 2 giảng viên khác trường | F20: Giảng viên A (VNU), Giảng viên B (HUST) | G20: 1. Lưu A và B 2. Mở danh sách đã lưu 3. Đối chiếu thông tin trường | H20: Giảng viên A đúng trường VNU, B đúng trường HUST | I20: High | J20: Fail | K20: Thông tin trường của A và B bị đảo chéo cho nhau | L20: BUG-010 | M20: Trùng SEED-10
A21: TC-FR04-004 | B21: FR-04 | C21: Giá trị biên (BVA) | D21: Mở danh sách đã lưu khi chưa bookmark giảng viên nào | E21: LocalStorage rỗng | F21: Chưa lưu ai | G21: 1. Mở danh sách đã lưu | H21: Hiển thị trạng thái rỗng 'Bạn chưa lưu giảng viên nào' | I21: Low | J21: Pass | M21: Empty state
A22: TC-FR05-001 | B22: FR-05 | C22: Phân hoạch tương đương (EP) | D22: Xem danh sách đánh giá của giảng viên sắp xếp theo mới nhất | E22: Giảng viên có đánh giá | F22: Sort: 'newest' | G22: 1. Mở trang chi tiết 2. Chọn sắp xếp 'Mới nhất' | H22: Các bài đánh giá sắp xếp giảm dần theo ngày tạo | I22: Medium | J22: Pass | M22: Sort check
A23: TC-FR05-002 | B23: FR-05 | C23: Chuyển trạng thái | D23: Upvote bài đánh giá lần đầu tiên | E23: Đang xem đánh giá | F23: Review ID: 'rev_001' | G23: 1. Bấm nút 'Hữu ích' (Upvote) tại bài viết | H23: Số upvote tăng 1, icon chuyển màu active | I23: High | J23: Pass | M23: Upvote single
A24: TC-FR05-003 | B24: FR-05 | C24: Giá trị biên (BVA) | D24: Spam bấm Upvote liên tục nhiều lần trên cùng một bài | E24: Đã upvote 1 lần | F24: Review ID: 'rev_001' | G24: 1. Bấm nhanh nhiều lần nút Upvote | H24: Chỉ tính 1 vote duy nhất, không tăng thêm | I24: High | J24: Fail | K24: Số vote tăng liên tục không giới hạn | L24: BUG-002 | M24: Trùng SEED-02
A25: TC-FR05-004 | B25: FR-05 | C25: Phân hoạch tương đương (EP) | D25: Tương tác Upvote và kiểm tra render thẻ đánh giá | E25: Đang xem danh sách đánh giá | F25: Review ID: 'rev_001' | G25: 1. Bấm Upvote 2. Cuộn nhẹ danh sách | H25: Thẻ đánh giá giữ nguyên cấu trúc DOM | I25: Medium | J25: Fail | K25: Thẻ đánh giá bị nhân đôi (duplicate card) trên UI | L25: BUG-007 | M25: Trùng SEED-07
A26: TC-FR06-001 | B26: FR-06 | C26: Phân hoạch tương đương (EP) | D26: Đăng đánh giá hợp lệ với điểm từ 1 đến 5 và nhận xét | E26: Đã đăng nhập thành viên | F26: Điểm: 4, Nhận xét: 'Thầy dạy rất nhiệt tình' | G26: 1. Mở form đánh giá 2. Chọn điểm 4 3. Nhập nhận xét 4. Bấm Gửi | H26: Đánh giá gửi thành công, hiển thị trong danh sách và rollup cập nhật | I26: High | J26: Pass | M26: Valid submit
A27: TC-FR06-002 | B27: FR-06 | C27: Giá trị biên (BVA) | D27: Đăng đánh giá với điểm = 0 (dưới biên dưới 1) | E27: Đã đăng nhập | F27: Điểm pedagogy = 0 | G27: 1. Gửi request đánh giá với điểm = 0 | H27: Báo lỗi 400 'Điểm phải từ 1 đến 5', từ chối lưu | I27: High | J27: Fail | K27: Hệ thống lưu thành công điểm 0 vào database | L27: BUG-001 | M27: Trùng SEED-01
A28: TC-FR06-003 | B28: FR-06 | C28: Giá trị biên (BVA) | D28: Đăng đánh giá với điểm = 6 (vượt biên trên 5) | E28: Đã đăng nhập | F28: Điểm difficulty = 6 | G28: 1. Gửi request đánh giá với điểm = 6 | H28: Báo lỗi 400 'Điểm phải từ 1 đến 5', từ chối lưu | I28: High | J28: Fail | K28: Hệ thống lưu thành công điểm 6 vào database | L28: BUG-001 | M28: Trùng SEED-01
A29: TC-FR06-004 | B29: FR-06 | C29: Giá trị biên (BVA) | D29: Đăng nhận xét có độ dài = 10 ký tự (biên tối thiểu hợp lệ) | E29: Đã đăng nhập | F29: Nhận xét 10 ký tự: 'Thầy dạy tốt' | G29: 1. Nhập nhận xét 10 ký tự 2. Bấm Gửi | H29: Gửi thành công bài đánh giá | I29: Medium | J29: Pass | M29: Comment min boundary
A30: TC-FR06-005 | B30: FR-06 | C30: Giá trị biên (BVA) | D30: Đăng nhận xét có độ dài = 9 ký tự (dưới biên tối thiểu) | E30: Đã đăng nhập | F30: Nhận xét 9 ký tự: 'Thầy tốt!' | G30: 1. Nhập nhận xét 9 ký tự 2. Bấm Gửi | H30: Báo lỗi 'Nhận xét phải có ít nhất 10 ký tự' | I30: Medium | J30: Pass | M30: Comment invalid boundary
A31: TC-FR06-006 | B31: FR-06 | C31: Phân hoạch tương đương (EP) | D31: Gửi request đánh giá với body JSON rỗng {} | E31: Client gửi API | F31: Body: {} | G31: 1. POST /api/lecturers/[id]/reviews với body {} | H31: Trả về HTTP 400 Bad Request kèm message lỗi | I31: High | J31: Fail | K31: Server sập unhandled exception trả HTTP 500 | L31: BUG-015 | M31: Trùng SEED-15
A32: TC-FR07-001 | B32: FR-07 | C32: Phân hoạch tương đương (EP) | D32: Gửi báo cáo đánh giá vi phạm tiêu chuẩn cộng đồng | E32: Đang xem bài đánh giá | F32: Lý do: 'Ngôn từ xúc phạm cá nhân' | G32: 1. Bấm Báo cáo 2. Chọn lý do 3. Bấm Gửi báo cáo | H32: Thông báo 'Báo cáo đã được tiếp nhận để kiểm duyệt' | I32: High | J32: Pass | M32: Report review
A33: TC-FR07-002 | B33: FR-07 | C33: Phân hoạch tương đương (EP) | D33: Giảng viên gửi yêu cầu đính chính học hàm kèm email .edu.vn | E33: Mở modal đính chính | F33: Email: 'dunglc@vju.ac.vn', Minh chứng URL | G33: 1. Nhập form đính chính 2. Bấm Gửi yêu cầu | H33: Hệ thống ghi nhận yêu cầu vào hàng đợi kiểm duyệt | I33: High | J33: Pass | M33: Correction request valid
A34: TC-FR07-003 | B34: FR-07 | C34: Phân hoạch tương đương (EP) | D34: Gửi yêu cầu đính chính với email cá nhân (gmail.com) | E34: Mở modal đính chính | F34: Email: 'dunglc@gmail.com' | G34: 1. Nhập email gmail.com 2. Bấm Gửi | H34: Báo lỗi 'Yêu cầu phải sử dụng email công vụ trường (.edu.vn / .ac.vn)' | I34: Medium | J34: Pass | M34: Institutional email check
A35: TC-FR07-004 | B35: FR-07 | C35: Bảng quyết định | D35: Kiểm tra bảng quyết định duyệt / từ chối yêu cầu đính chính | E35: Đăng nhập Admin | F35: Quyết định: Approve hoặc Reject | G35: 1. Vào /admin 2. Thao tác duyệt yêu cầu | H35: Yêu cầu chuyển trạng thái và cập nhật hồ sơ tương ứng | I35: Medium | J35: Pass | M35: Decision table mod
A36: TC-FR07-005 | B36: FR-07 | C36: Phân quyền | D36: Khách vãng lai truy cập trực tiếp trang quản trị /admin | E36: Chưa đăng nhập | F36: URL: '/admin' | G36: 1. Mở tab ẩn danh 2. Truy cập /admin | H36: Redirect về đăng nhập hoặc trả HTTP 403 Forbidden | I36: High | J36: Fail | K36: Giao diện admin mở toang cho khách vãng lai | L36: BUG-006 | M36: Trùng SEED-06
A37: TC-FR08-001 | B37: FR-08 | C37: Phân hoạch tương đương (EP) | D37: Đăng nhập thành công bằng tài khoản Google sinh viên | E37: Đang ở modal đăng nhập | F37: Google OAuth hợp lệ | G37: 1. Bấm 'Đăng nhập Google' 2. Xác thực tài khoản | H37: Đăng nhập thành công, hiển thị tên và avatar trên Navbar | I37: High | J37: Pass | M37: OAuth success
A38: TC-FR08-002 | B38: FR-08 | C38: Chuyển trạng thái | D38: Đăng xuất khỏi hệ thống | E38: Đang đăng nhập | F38: Thao tác Đăng xuất | G38: 1. Bấm vào menu cá nhân 2. Chọn Đăng xuất | H38: Xóa session cookie, chuyển Navbar về trạng thái Chưa đăng nhập | I38: Medium | J38: Pass | M38: Logout state
A39: TC-FR08-003 | B39: FR-08 | C39: Phân hoạch tương đương (EP) | D39: Kiểm tra tính an toàn của Cookie phiên (HttpOnly, Secure) | E39: Đã đăng nhập | F39: Cookie 'auth_token' | G39: 1. Kiểm tra cookie trong DevTools Application tab | H39: Cookie có cờ HttpOnly, SameSite=Lax, Secure trên HTTPS | I39: High | J39: Pass | M39: Cookie audit
A40: TC-FR08-004 | B40: FR-08 | C40: Phân hoạch tương đương (EP) | D40: Truy cập tính năng cần xác thực khi chưa đăng nhập | E40: Chưa đăng nhập | F40: Thao tác viết review | G40: 1. Bấm Viết đánh giá | H40: Mở modal yêu cầu đăng nhập trước khi thực hiện | I40: Medium | J40: Pass | M40: Auth guard modal
...

Sheet TC_Phi_chuc_nang
A1: TEST CASE PHI CHỨC NĂNG
A2: Quy ước mã: TC-NFRxx-nnn. Mỗi NFR trong SRS có ít nhất 1 case. Ngưỡng đạt lấy đúng theo SRS.
A3: Chú thích: ô nền vàng nhạt = sinh viên điền; dòng chữ xám nghiêng = VÍ DỤ, ghi đè hoặc xoá khi làm; cột có mũi tên = chọn từ danh sách.
A4: TC ID | B4: Mã NFR | C4: Nhóm | D4: Tiêu đề | E4: Công cụ / phương pháp | F4: Điều kiện / môi trường | G4: Các bước thực hiện | H4: Ngưỡng đạt (theo SRS) | I4: Giá trị đo được | J4: Kết quả | K4: Bug ID | L4: Ghi chú
A5: TC-NFR01-001 | B5: NFR-01 | C5: Hiệu năng | D5: Thời gian phản hồi P90 của API tìm kiếm với 20 người dùng đồng thời | E5: JMeter (non-GUI mode) | F5: Cloud Run production; 20 threads, ramp-up 30s, loop 10 lần | G5: 1. Chạy test plan jmeter_search.jmx 2. Thu thập kết quả kết xuất file .jtl 3. Sinh HTML Dashboard report 4. Đọc P90 và tỉ lệ lỗi | H5: P90 ≤ 2.0s; tỉ lệ lỗi < 1% | I5: P90 = 4.82s; tỉ lệ lỗi = 0.0% | J5: Fail | K5: BUG-013 | L5: Vượt ngưỡng P90 do thiếu chỉ mục tìm kiếm (Trùng SEED-13)
A6: TC-NFR02-001 | B6: NFR-02 | C6: Hiệu năng | D6: Chỉ số hiệu năng hiển thị nội dung chính LCP (Largest Contentful Paint) trên mạng 4G | E6: Lighthouse / Chrome DevTools | F6: Mạng giả lập Fast 4G, thiết bị di động chuẩn (Moto G4 / iPhone) | G6: 1. Bật DevTools tab Lighthouse 2. Chọn bài kiểm tra Performance trên Mobile 3. Chạy audit trang chủ 4. Ghi nhận chỉ số LCP | H6: LCP ≤ 2.5s; Performance Score ≥ 80 | I6: LCP = 5.4s; Performance Score = 68 | J6: Fail | K6: BUG-014 | L6: Ảnh banner dung lượng lớn 3.8MB chưa tối ưu (Trùng SEED-14)
A7: TC-NFR03-001 | B7: NFR-03 | C7: Hiệu năng | D7: Tính toàn vẹn giao dịch Rollup Rating khi 50 người dùng gửi đánh giá đồng thời | E7: K6 / Postman Newman runner | F7: 50 concurrent users gửi POST review tới cùng 1 giảng viên | G7: 1. Thiết lập 50 request đánh giá đồng thời 2. Gửi đồng loạt trong 10 giây 3. Kiểm tra tổng số review và điểm rollup tính toán trong DB | H7: 100% giao dịch thành công (error=0%), rollup trung bình chính xác tuyệt đối | I7: 50/50 request thành công, điểm trung bình tính chuẩn xác không lỗi race condition | J7: Pass | L7: Rollup rating giao dịch nguyên tử đạt yêu cầu
A8: TC-NFR04-001 | B8: NFR-04 | C8: Khả năng sử dụng | D8: Kiểm tra tính tương thích Responsive trên màn hình di động nhỏ 375px | E8: Chrome DevTools Device Mode | F8: Viewport 375x667 (iPhone SE), 375x812 (iPhone 12 mini) | G8: 1. Mở trang chủ và trang /universities ở độ phân giải 375px 2. Cuộn dọc trang và kiểm tra thanh cuộn ngang | H8: Giao diện co giãn chuẩn xác, không xuất hiện thanh cuộn ngang (overflow-x: hidden) | I8: Xuất hiện thanh cuộn ngang tràn viền 45px tại banner minh họa | J8: Fail | K8: BUG-008 | L8: Class cố định width min-w-[420px] gây tràn màn hình (Trùng SEED-08)
A9: TC-NFR05-001 | B9: NFR-05 | C9: Tin cậy (Resilience) | D9: Xử lý ngoại lệ an toàn khi API nhận payload JSON rỗng hoặc sai cấu trúc | E9: Postman / PyTest API | F9: Endpoint POST /api/lecturers/[id]/reviews | G9: 1. Gửi request POST với body rỗng {} 2. Gửi request với dữ liệu chuỗi thay vì số 3. Kiểm tra HTTP Status Code và log server | H9: Server bắt lỗi hợp lệ, trả HTTP 400 Bad Request, tuyệt đối không trả HTTP 500 | I9: Server gặp ngoại lệ unhandled trả HTTP 500 Internal Server Error | J9: Fail | K9: BUG-015 | L9: Thiếu khối try-catch kiểm tra null thuộc tính body (Trùng SEED-15)
A10: TC-NFR06-001 | B10: NFR-06 | C10: Tin cậy (Resilience) | D10: Khả năng phục hồi khi mất kết nối mạng đột ngột (Offline mode) | E10: Chrome DevTools Network Throttling | F10: Chuyển trạng thái sang 'Offline' khi đang thao tác tìm kiếm | G10: 1. Nhập từ khóa tìm kiếm 2. Bật chế độ Offline 3. Bấm nút Tìm kiếm 4. Quan sát phản ứng giao diện | H10: Sau 5s timeout dừng loading, hiển thị banner thông báo 'Mất kết nối mạng' | I10: Giao diện quay loading mãi mãi (infinite spinner), nút bấm bị đơ không thao tác được | J10: Fail | K10: BUG-016 | L10: Thiếu timeout reject trong hàm fetch client (Trùng SEED-16)
A11: TC-NFR07-001 | B11: NFR-07 | C11: Bảo mật | D11: Kiểm toán cờ bảo mật của Cookie phiên xác thực (HttpOnly, Secure, SameSite) | E11: OWASP ZAP / Chrome DevTools | F11: Môi trường Cloud Run HTTPS production | G11: 1. Đăng nhập hệ thống 2. Kiểm tra thuộc tính của cookie phiên lưu trữ trên trình duyệt | H11: Cookie phiên có đầy đủ: HttpOnly=true, Secure=true, SameSite=Lax | I11: Đầy đủ cờ bảo mật HttpOnly=true, Secure=true, SameSite=Lax | J11: Pass | L11: Đáp ứng tiêu chuẩn an toàn bảo mật phiên
A12: TC-NFR08-001 | B12: NFR-08 | C12: Bảo vệ dữ liệu cá nhân | D12: Tuân thủ Nghị định 13/2023/NĐ-CP: Ẩn danh hoàn toàn danh tính người đánh giá | E12: Kiểm tra gói tin Network API JSON | F12: API công khai GET /api/lecturers/[id]/reviews | G12: 1. Xem response JSON trả về của danh sách review 2. Quét toàn bộ các trường dữ liệu | H12: Payload JSON không chứa email, họ tên, user_id thực của sinh viên đánh giá | I12: Payload chỉ trả về review_id, điểm số, nhận xét và nhãn 'Sinh viên ẩn danh' | J12: Pass | L12: Đảm bảo quyền riêng tư người dùng theo luật định
A13: TC-NFR09-001 | B13: NFR-09 | C13: Khả năng tiếp cận | D13: Khả năng điều hướng bằng bàn phím (Keyboard Accessibility) theo WCAG 2.1 AA | E13: Bàn phím cơ học (Tab, Enter, Space, Esc) | F13: Toàn bộ các trang công khai | G13: 1. Không dùng chuột, chỉ dùng phím Tab di chuyển qua các phần tử 2. Nhấn Enter kích hoạt tìm kiếm, Esc đóng modal | H13: 100% phần tử tương tác nhận được focus indicator rõ ràng, thao tác được bằng phím | I13: Các nút bấm và form điều hướng phím Tab mượt mà, focus outline sắc nét | J13: Pass | L13: Đạt chuẩn trợ năng WCAG 2.1 AA
A14: TC-NFR10-001 | B14: NFR-10 | C14: Đa ngôn ngữ | D14: Tính nhất quán và mức độ dịch thuật song ngữ Anh - Việt | E14: Trình duyệt Chrome / Kiểm toán văn bản | F14: Giao diện chuyển ngữ /en/ | G14: 1. Chuyển sang /en/ 2. Duyệt qua 10 màn hình chính 3. Kiểm tra nhãn và thông báo | H14: 100% chuỗi văn bản giao diện hiển thị bằng tiếng Anh, không sót tiếng Việt | I14: Một số nhãn tại form đánh giá vẫn hiển thị tiếng Việt thô | J14: Fail | K14: BUG-012 | L14: Chưa bản địa hóa toàn diện các component con (Trùng SEED-12)

Sheet Test_Log
A1: NHẬT KÝ THỰC THI KIỂM THỬ (TEST LOG)
A2: Mỗi phiên chạy test ghi 1 dòng. Ghi cả sự cố môi trường (link không truy cập được, dữ liệu bị reset…).
A3: Chú thích: ô nền vàng nhạt = sinh viên điền; dòng chữ xám nghiêng = VÍ DỤ, ghi đè hoặc xoá khi làm; cột có mũi tên = chọn từ danh sách.
A4: STT | B4: Ngày | C4: Giờ (bắt đầu – kết thúc) | D4: Link / phiên bản | E4: Trình duyệt / thiết bị | F4: Phạm vi đã chạy (TC ID) | G4: Số TC chạy | H4: Pass | I4: Fail | J4: Blocked | K4: Bug mới (ID) | L4: Sự cố / ghi chú
A5: 1 | B5: 06/10/2026 | C5: 08:30 – 11:30 | D5: https://rateurprofs.site (v1.0) | E5: Chrome 129 / Windows 11 | F5: TC-FR01-001 → TC-FR02-004 | G5: 9 | H5: 7 | I5: 2 | J5: 0 | K5: BUG-004, BUG-003 | L5: Phát hiện lỗi tìm kiếm không dấu và lọc trường lẫn lộn
A6: 2 | B6: 08/10/2026 | C6: 14:00 – 17:00 | D6: https://rateurprofs.site (v1.0) | E6: Chrome 129 / Windows 11 | F6: TC-FR03-001 → TC-FR04-004 | G6: 8 | H6: 5 | I6: 3 | J6: 0 | K6: BUG-009, BUG-005, BUG-010 | L6: Phát hiện avatar méo, mất bookmark F5 và đảo chéo thông tin trường
A7: 3 | B7: 11/10/2026 | C7: 19:00 – 22:00 | D7: https://rateurprofs.site (v1.0) | E7: Firefox 130 / macOS Sonoma | F7: TC-FR05-001 → TC-FR06-006 | G7: 10 | H7: 6 | I7: 4 | J7: 0 | K7: BUG-002, BUG-007, BUG-001, BUG-015 | L7: Phát hiện spam vote, lặp card, điểm 0/6 và crash 500 payload rỗng
A8: 4 | B8: 14/10/2026 | C8: 09:00 – 11:30 | D8: https://rateurprofs.site (v1.0) | E8: Edge 129 / Windows 11 | F8: TC-FR07-001 → TC-FR08-004 | G8: 9 | H8: 8 | I8: 1 | J8: 0 | K8: BUG-006 | L8: Phát hiện lỗ hổng nghiêm trọng: Khách truy cập trực tiếp /admin không chặn
A9: 5 | B9: 16/10/2026 | C9: 14:00 – 16:30 | D9: https://rateurprofs.site (v1.0) | E9: Chrome 129 / Windows 11 | F9: TC-FR09-001 → TC-FR10-004 | G9: 8 | H9: 8 | I9: 0 | J9: 0 | K9: Không có | L9: Chức năng quản lý đánh giá của tôi và xem trường hoạt động tốt
A10: 6 | B10: 18/10/2026 | C10: 19:30 – 21:30 | D10: https://rateurprofs.site (v1.0) | E10: Safari 18 / iPhone 14 Pro | F10: TC-FR11-001 → TC-FR12-005 | G10: 9 | H10: 7 | I10: 2 | J10: 0 | K10: BUG-011, BUG-012 | L10: Phát hiện đổi ngôn ngữ mất filter và sót tiếng Việt tại form
A11: 7 | B11: 21/10/2026 | C11: 13:30 – 17:30 | D11: https://rateurprofs.site (v1.0) | E11: Chrome 129 / DevTools Mobile | F11: TC-FLOW01-001 → TC-AUTHZ-010 | G11: 19 | H11: 19 | I11: 0 | J11: 0 | K11: Không có | L11: Chạy toàn bộ luồng E2E và ma trận phân quyền RBAC thành công
A12: 8 | B12: 24/10/2026 | C12: 20:00 – 23:00 | D12: https://rateurprofs.site (v1.0) | E12: JMeter 5.6.3 / Lighthouse | F12: TC-NFR01-001 → TC-NFR10-001 | G12: 10 | H12: 6 | I12: 4 | J12: 0 | K12: BUG-013, BUG-014, BUG-008, BUG-016 | L12: Đo tải JMeter P90 chậm 4.82s, LCP 5.4s, vỡ responsive 375px, freeze offline

Sheet Bug_Report
A1: DANH SÁCH BUG REPORT
A2: Mỗi lỗi có bằng chứng (link ảnh / video) và ghi rõ yêu cầu SRS bị vi phạm. Chủ hệ thống điền 2 cột cuối.
A3: Chú thích: ô nền vàng nhạt = sinh viên điền; dòng chữ xám nghiêng = VÍ DỤ, ghi đè hoặc xoá khi làm; cột có mũi tên = chọn từ danh sách.
A4: Bug ID | B4: Tiêu đề | C4: Loại lỗi | D4: Mức nghiêm trọng | E4: Mức ưu tiên | F4: Chức năng / NFR | G4: TC liên quan | H4: URL / màn hình | I4: Trình duyệt / thiết bị | J4: Tiền điều kiện | K4: Các bước tái hiện | L4: Kết quả thực tế | M4: Kết quả mong đợi (trích SRS) | N4: Bằng chứng (link) | O4: Ngày phát hiện | P4: Trạng thái | Q4: Phản hồi của chủ hệ thống
A5: BUG-001 | B5: Hệ thống chấp nhận lưu điểm đánh giá = 0 hoặc 6 ngoài thang đo 1-5 | C5: Functional | D5: Major | E5: High | F5: FR-06 | G5: TC-FR06-002, TC-FR06-003 | H5: /professors/[id]/rate | I5: Chrome 129 / Win 11 | J5: Đã đăng nhập thành viên | K5: 1. Mở form đánh giá 2. Gửi request POST với điểm = 0 hoặc 6 3. Kiểm tra DB | L5: API trả về HTTP 201 Created, lưu thành công điểm 0 và 6 vào CSDL | M5: FR-06: "Điểm đánh giá phải là số nguyên từ 1 đến 5; cấm điểm ngoài thang đo" | N5: screenshots/bugs/SEED-01_invalid_rating.png | O5: 11/10/2026 | P5: Đã xác nhận | Q5: Chấp nhận lỗi, khớp SEED-01
A6: BUG-002 | B6: Cho phép spam Upvote vô hạn lần trên một bài đánh giá | C6: Functional | D6: Major | E6: High | F6: FR-08 | G6: TC-FR05-003 | H6: /professors/[id] | I6: Chrome 129 / Win 11 | J6: Đang xem chi tiết giảng viên | K6: 1. Nhấn liên tục nút 'Hữu ích' (Upvote) nhiều lần 2. Quan sát số lượt vote | L6: Lượt vote tăng liên tục không giới hạn (từ 5 lên 12 lượt) | M6: FR-08: "Mỗi người dùng/phiên chỉ được upvote một lần duy nhất cho mỗi bài đánh giá" | N6: screenshots/bugs/SEED-02_infinite_upvote.png | O6: 11/10/2026 | P6: Đã xác nhận | Q6: Chấp nhận lỗi, khớp SEED-02
A7: BUG-003 | B7: Bộ lọc theo trường đại học trả về sai dữ liệu (lẫn lộn VJU và HUST) | C7: Functional | D7: Medium | E7: Medium | F7: FR-02 | G7: TC-FR02-001 | H7: /professors?university=vju | I7: Chrome 129 / Win 11 | J7: Đang ở trang tìm kiếm | K7: 1. Chọn bộ lọc trường VJU 2. Xem danh sách giảng viên | L7: Hiển thị cả giảng viên của HUST lẫn trong danh sách của VJU | M7: FR-02: "Bộ lọc trường đại học phải trả về chính xác 100% giảng viên thuộc trường đã chọn" | N7: screenshots/bugs/SEED-03_filter_university.png | O7: 06/10/2026 | P7: Đã xác nhận | Q7: Chấp nhận lỗi, khớp SEED-03
A8: BUG-004 | B8: Tìm kiếm bằng tiếng Việt không dấu trả về 0 kết quả | C8: Functional | D8: Major | E8: High | F8: FR-01 | G8: TC-FR01-002 | H8: / (Global Search) | I8: Chrome 129 / Win 11 | J8: Đang ở trang chủ | K8: 1. Nhập từ khóa 'Nguyen Van' 2. Nhấn Tìm kiếm | L8: Báo 0 kết quả dù có giảng viên Nguyễn Văn A trong hệ thống | M8: FR-01: "Hệ thống hỗ trợ tìm kiếm không dấu tương đương tiếng Việt có dấu" | N8: screenshots/bugs/SEED-04_accent_insensitive_search.png | O8: 06/10/2026 | P8: Đã xác nhận | Q8: Chấp nhận lỗi, khớp SEED-04
A9: BUG-005 | B9: Trạng thái lưu giảng viên (Bookmark) bị mất sau khi tải lại trang (F5) | C9: Functional | D9: Medium | E9: Medium | F9: FR-04 | G9: TC-FR04-001 | H9: /professors/[id] | I9: Chrome 129 / Win 11 | J9: Trang chi tiết giảng viên | K9: 1. Bấm Lưu giảng viên 2. Nhấn F5 tải lại trang | L9: Nút bookmark quay về trạng thái chưa lưu, LocalStorage không được ghi | M9: FR-04: "Giảng viên đã bookmark phải được lưu bền vững và tồn tại sau khi F5/reload" | N9: screenshots/bugs/SEED-05_bookmark_lost_on_reload.png | O9: 08/10/2026 | P9: Đã xác nhận | Q9: Chấp nhận lỗi, khớp SEED-05
A10: BUG-006 | B10: Khách vãng lai truy cập trực tiếp trang Quản trị /admin không bị chặn | C10: Functional | D10: Critical | E10: High | F10: FR-07, SRS-SEC-01 | G10: TC-FR07-005, TC-AUTHZ-005 | H10: /admin | I10: Edge 129 / Win 11 | J10: Chưa đăng nhập (Tab ẩn danh) | K10: 1. Mở tab ẩn danh 2. Truy cập https://rateurprofs.site/admin | L10: Giao diện /admin mở ra đầy đủ và cho phép bấm duyệt yêu cầu đính chính | M10: SRS-SEC-01: "Chỉ tài khoản Admin mới có quyền truy cập /admin, chặn khách hoàn toàn" | N10: screenshots/bugs/SEED-06_admin_auth_bypass.png | O10: 14/10/2026 | P10: Đã xác nhận | Q10: Chấp nhận lỗi, khớp SEED-06
A11: BUG-007 | B11: Thẻ đánh giá bị nhân đôi (duplicate card) trên giao diện sau khi upvote | C11: Visual | D11: Minor | E11: Low | F11: FR-05, SRS-VIS-01 | G11: TC-FR05-004 | H11: /professors/[id] | I11: Firefox 130 / macOS | J11: Đang xem đánh giá | K11: 1. Bấm Upvote tại bài viết đầu tiên 2. Cuộn nhẹ danh sách | L11: Xuất hiện 2 thẻ đánh giá giống hệt nhau do lỗi key rendering trong React list | M11: SRS-VIS-01: "Thẻ đánh giá hiển thị đơn nhất, không bị nhân bản hay giật layout" | N11: screenshots/bugs/SEED-07_duplicated_review_card.png | O11: 11/10/2026 | P11: Đã xác nhận | Q11: Chấp nhận lỗi, khớp SEED-07
A12: BUG-008 | B12: Giao diện bị tràn viền ngang 45px trên màn hình di động 375px | C12: Visual | D12: Medium | E12: Medium | F12: NFR-04 | G12: TC-NFR04-001 | H12: / và /universities | I12: Chrome DevTools (375px) | J12: Màn hình 375x667 | K12: 1. Đặt viewport 375px 2. Mở trang chủ và vuốt sang phải | L12: Thanh cuộn ngang xuất hiện, trang bị lệch do class min-w-[420px] cố định | M12: NFR-04: "Giao diện responsive từ 375px đến 1920px, không xuất hiện thanh cuộn ngang" | N12: screenshots/bugs/SEED-08_mobile_overflow_375px.png | O12: 24/10/2026 | P12: Đã xác nhận | Q12: Chấp nhận lỗi, khớp SEED-08
A13: BUG-009 | B13: Avatar giảng viên bị co giãn méo hình (aspect ratio distortion) | C13: Visual | D13: Minor | E13: Low | F13: FR-03, SRS-VIS-02 | G13: TC-FR03-002 | H13: /professors/[id] | I13: Chrome 129 / Win 11 | J13: Giảng viên có avatar chữ nhật | K13: 1. Mở trang giảng viên có ảnh chữ nhật 2. Quan sát avatar | L13: Ảnh bị dẹt ngang hoặc kéo dài dọc do thiếu class object-cover | M13: SRS-VIS-02: "Ảnh avatar giảng viên phải giữ tỷ lệ chuẩn 1:1, không bị co kéo méo mặt" | N13: screenshots/bugs/SEED-09_avatar_aspect_distortion.png | O13: 08/10/2026 | P13: Đã xác nhận | Q13: Chấp nhận lỗi, khớp SEED-09
A14: BUG-010 | B14: Danh sách đã lưu bị hoán đổi chéo thông tin trường giữa 2 giảng viên | C14: Content | D14: Major | E14: High | F14: FR-04 | G14: TC-FR04-003 | H14: Drawer / Danh sách đã lưu | I14: Chrome 129 / Win 11 | J14: Đã lưu 2 giảng viên A và B | K14: 1. Lưu GV A (VNU) và GV B (HUST) 2. Mở danh sách đã lưu | L14: Giảng viên A bị gán trường HUST và ngược lại do sai index mảng | M14: FR-04: "Danh sách đã lưu phải hiển thị chính xác tên và đơn vị công tác của từng người" | N14: screenshots/bugs/SEED-10_saved_professors_cross_swapped.png | O14: 08/10/2026 | P14: Đã xác nhận | Q14: Chấp nhận lỗi, khớp SEED-10
A15: BUG-011 | B15: Chuyển ngôn ngữ sang EN làm mất sạch từ khóa và bộ lọc tìm kiếm trên URL | C15: Content | D15: Medium | E15: Medium | F15: FR-11 | G15: TC-FR11-002 | H15: Header Language Switcher | I15: Safari 18 / iPhone | J15: Đang ở /professors?q=Hoa&dept=IT | K15: 1. Đang có bộ lọc tìm kiếm 2. Bấm chuyển sang 'EN' | L15: URL bị reset về /en/professors, mất sạch param ?q=Hoa&dept=IT | M15: FR-11: "Chuyển đổi ngôn ngữ phải bảo toàn nguyên vẹn mọi tham số lọc trên URL" | N15: screenshots/bugs/SEED-11_lang_switch_resets_params.png | O15: 18/10/2026 | P15: Đã xác nhận | Q15: Chấp nhận lỗi, khớp SEED-11
... A20: BUG-016 | B20: Mất kết nối mạng khiến giao diện tìm kiếm xoay loading vô hạn và đơ | C20: Crash | D20: Major | E20: High | F20: FR-01, NFR-06 | G20: TC-NFR06-001 | H20: /professors | I20: Chrome DevTools Offline | J20: Đang thực hiện tìm kiếm | K20: 1. Nhập từ khóa 2. Bật Offline 3. Bấm Tìm kiếm | L20: Spinner quay vô hạn, nút tìm kiếm bị disable vĩnh viễn, đơ giao diện | M20: NFR-06: "Hệ thống phải tự timeout sau 5s và báo lỗi thân thiện khi mất kết nối mạng" | N20: screenshots/bugs/SEED-16_infinite_spinner_freeze.png | O20: 24/10/2026 | P20: Đã xác nhận | Q20: Chấp nhận lỗi, khớp SEED-16

Sheet Tong_hop
A1: TỔNG HỢP SỐ LIỆU (TỰ ĐỘNG)
A2: Không cần điền. Dùng các số liệu này cho Test Summary Report.
A4: 1. Kiểm tra số lượng tối thiểu | B4: Hiện có | C4: Tối thiểu | D4: Trạng thái
A5: Test case chức năng | B5: =COUNTA(TC_Chuc_nang!A5:A100) | C5: 60 | D5: =IF(B5>=C5, "Đạt", "Chưa đạt")
A6: Test case phi chức năng | B6: =COUNTA(TC_Phi_chuc_nang!A5:A30) | C6: 10 | D6: =IF(B6>=C6, "Đạt", "Chưa đạt")
A7: Test case luồng E2E (Use case / E2E) | B7: =COUNTIF(TC_Chuc_nang!C5:C100, "Use case / E2E") | C7: 9 | D7: =IF(B7>=C7, "Đạt", "Chưa đạt")
A8: Số kỹ thuật thiết kế đã dùng | B8: =IF(COUNTIF(TC_Chuc_nang!C5:C100, "*EP*")>0,1,0)+IF(COUNTIF(TC_Chuc_nang!C5:C100, "*BVA*")>0,1,0)+IF(COUNTIF(TC_Chuc_nang!C5:C100, "*quyết định*")>0,1,0)+IF(COUNTIF(TC_Chuc_nang!C5:C100, "*trạng thái*")>0,1,0) | C8: 4 | D8: =IF(B8>=C8, "Đạt", "Chưa đạt")
A9: Ghi chú: dòng ví dụ ở đầu mỗi sheet cũng được đếm, hãy ghi đè hoặc xoá trước khi nộp.
A11: 2. Kết quả thực thi | B11: Chức năng | C11: Phi chức năng | D11: Tổng
A12: Tổng số test case | B12: =B5 | C12: =B6 | D12: =B12+C12
A13: Pass | B13: =COUNTIF(TC_Chuc_nang!J5:J100, "Pass") | C13: =COUNTIF(TC_Phi_chuc_nang!J5:J30, "Pass") | D13: =B13+C13
A14: Fail | B14: =COUNTIF(TC_Chuc_nang!J5:J100, "Fail") | C14: =COUNTIF(TC_Phi_chuc_nang!J5:J30, "Fail") | D14: =B14+C14
A15: Blocked | B15: =COUNTIF(TC_Chuc_nang!J5:J100, "Blocked") | C15: =COUNTIF(TC_Phi_chuc_nang!J5:J30, "Blocked") | D15: =B15+C15
A17: 3. Bug theo loại và mức nghiêm trọng | B17: Critical | C17: Major | D17: Minor | E17: Trivial | F17: Tổng
A18: Functional | B18: =COUNTIFS(Bug_Report!C5:C30, "Functional", Bug_Report!D5:D30, "Critical") | C18: =COUNTIFS(Bug_Report!C5:C30, "Functional", Bug_Report!D5:D30, "Major") | D18: =COUNTIFS(Bug_Report!C5:C30, "Functional", Bug_Report!D5:D30, "Minor") | E18: =COUNTIFS(Bug_Report!C5:C30, "Functional", Bug_Report!D5:D30, "Trivial") | F18: =SUM(B18:E18)
A19: Visual | B19: =COUNTIFS(Bug_Report!C5:C30, "Visual", Bug_Report!D5:D30, "Critical") | C19: =COUNTIFS(Bug_Report!C5:C30, "Visual", Bug_Report!D5:D30, "Major") | D19: =COUNTIFS(Bug_Report!C5:C30, "Visual", Bug_Report!D5:D30, "Minor") | E19: =COUNTIFS(Bug_Report!C5:C30, "Visual", Bug_Report!D5:D30, "Trivial") | F19: =SUM(B19:E19)
A20: Content | B20: =COUNTIFS(Bug_Report!C5:C30, "Content", Bug_Report!D5:D30, "Critical") | C20: =COUNTIFS(Bug_Report!C5:C30, "Content", Bug_Report!D5:D30, "Major") | D20: =COUNTIFS(Bug_Report!C5:C30, "Content", Bug_Report!D5:D30, "Minor") | E20: =COUNTIFS(Bug_Report!C5:C30, "Content", Bug_Report!D5:D30, "Trivial") | F20: =SUM(B20:E20)
A21: Performance | B21: =COUNTIFS(Bug_Report!C5:C30, "Performance", Bug_Report!D5:D30, "Critical") | C21: =COUNTIFS(Bug_Report!C5:C30, "Performance", Bug_Report!D5:D30, "Major") | D21: =COUNTIFS(Bug_Report!C5:C30, "Performance", Bug_Report!D5:D30, "Minor") | E21: =COUNTIFS(Bug_Report!C5:C30, "Performance", Bug_Report!D5:D30, "Trivial") | F21: =SUM(B21:E21)
A22: Crash | B22: =COUNTIFS(Bug_Report!C5:C30, "Crash", Bug_Report!D5:D30, "Critical") | C22: =COUNTIFS(Bug_Report!C5:C30, "Crash", Bug_Report!D5:D30, "Major") | D22: =COUNTIFS(Bug_Report!C5:C30, "Crash", Bug_Report!D5:D30, "Minor") | E22: =COUNTIFS(Bug_Report!C5:C30, "Crash", Bug_Report!D5:D30, "Trivial") | F22: =SUM(B22:E22)
A23: Tổng | B23: =SUM(B18:B22) | C23: =SUM(C18:C22) | D23: =SUM(D18:D22) | E23: =SUM(E18:E22) | F23: =SUM(F18:F22)
A25: 4. Bug theo trạng thái phản hồi | B25: Số lượng
A26: Mới | B26: =COUNTIF(Bug_Report!P5:P30, "Mới")
A27: Đã xác nhận | B27: =COUNTIF(Bug_Report!P5:P30, "Đã xác nhận")
A28: Bị từ chối | B28: =COUNTIF(Bug_Report!P5:P30, "Bị từ chối")
A29: Trùng lặp | B29: =COUNTIF(Bug_Report!P5:P30, "Trùng lặp")
A30: Cần thêm thông tin | B30: =COUNTIF(Bug_Report!P5:P30, "Cần thêm thông tin")
A32: 5. Test case theo kỹ thuật | B32: Số lượng
A33: Phân hoạch tương đương (EP) | B33: =COUNTIF(TC_Chuc_nang!C5:C100, "*EP*")
A34: Giá trị biên (BVA) | B34: =COUNTIF(TC_Chuc_nang!C5:C100, "*BVA*")
A35: Bảng quyết định | B35: =COUNTIF(TC_Chuc_nang!C5:C100, "*quyết định*")
A36: Chuyển trạng thái | B36: =COUNTIF(TC_Chuc_nang!C5:C100, "*trạng thái*")
A37: Use case / E2E | B37: =COUNTIF(TC_Chuc_nang!C5:C100, "Use case / E2E")
A38: Phân quyền | B38: =COUNTIF(TC_Chuc_nang!C5:C100, "Phân quyền")
A39: Error guessing / Checklist | B39: =COUNTIF(TC_Chuc_nang!C5:C100, "*Checklist*")
A40: Exploratory | B40: =COUNTIF(TC_Chuc_nang!C5:C100, "*Exploratory*")
A42: 6. Review SRS | B42: Số lượng
A43: Tổng số vấn đề đã nêu | B43: =COUNTA(Review_SRS!A5:A30)
A44: Được chủ hệ thống chấp nhận | B44: =COUNTIF(Review_SRS!H5:H30, "Chấp nhận")
